2022-12-07 00:04:01,445 INFO    StreamThr :2686020 [internal.py:wandb_internal():90] W&B internal server running at pid: 2686020, started at: 2022-12-07 00:04:01.443923
2022-12-07 00:04:01,451 DEBUG   HandlerThread:2686020 [handler.py:handle_request():139] handle_request: status
2022-12-07 00:04:01,454 DEBUG   SenderThread:2686020 [sender.py:send_request():317] send_request: status
2022-12-07 00:04:01,456 DEBUG   SenderThread:2686020 [sender.py:send():303] send: header
2022-12-07 00:04:01,456 INFO    WriterThread:2686020 [datastore.py:open_for_write():75] open: /home/dongheng/LLMR/wandb/run-20221207_000401-22gc4n5r/run-22gc4n5r.wandb
2022-12-07 00:04:01,461 DEBUG   SenderThread:2686020 [sender.py:send():303] send: run
2022-12-07 00:04:01,795 ERROR   SenderThread:2686020 [internal_api.py:execute():212] 403 response executing GraphQL.
2022-12-07 00:04:01,795 ERROR   SenderThread:2686020 [internal_api.py:execute():213] {"errors":[{"message":"permission denied","path":["upsertBucket"],"extensions":{"code":"PERMISSION_ERROR"}}],"data":{"upsertBucket":null}}
2022-12-07 00:04:02,461 INFO    WriterThread:2686020 [datastore.py:close():279] close: /home/dongheng/LLMR/wandb/run-20221207_000401-22gc4n5r/run-22gc4n5r.wandb
2022-12-07 00:04:02,462 INFO    HandlerThread:2686020 [handler.py:finish():814] shutting down handler
2022-12-07 00:04:02,462 ERROR   StreamThr :2686020 [internal.py:wandb_internal():162] Thread SenderThread:
Traceback (most recent call last):
  File "/home/dongheng/.conda/envs/LLMR/lib/python3.7/site-packages/wandb/sdk/lib/retry.py", line 113, in __call__
    result = self._call_fn(*args, **kwargs)
  File "/home/dongheng/.conda/envs/LLMR/lib/python3.7/site-packages/wandb/sdk/internal/internal_api.py", line 209, in execute
    return self.client.execute(*args, **kwargs)  # type: ignore
  File "/home/dongheng/.conda/envs/LLMR/lib/python3.7/site-packages/wandb/vendor/gql-0.2.0/wandb_gql/client.py", line 52, in execute
    result = self._get_result(document, *args, **kwargs)
  File "/home/dongheng/.conda/envs/LLMR/lib/python3.7/site-packages/wandb/vendor/gql-0.2.0/wandb_gql/client.py", line 60, in _get_result
    return self.transport.execute(document, *args, **kwargs)
  File "/home/dongheng/.conda/envs/LLMR/lib/python3.7/site-packages/wandb/vendor/gql-0.2.0/wandb_gql/transport/requests.py", line 39, in execute
    request.raise_for_status()
  File "/home/dongheng/.conda/envs/LLMR/lib/python3.7/site-packages/requests/models.py", line 1021, in raise_for_status
    raise HTTPError(http_error_msg, response=self)
requests.exceptions.HTTPError: 403 Client Error: Forbidden for url: https://api.wandb.ai/graphql

During handling of the above exception, another exception occurred:

Traceback (most recent call last):
  File "/home/dongheng/.conda/envs/LLMR/lib/python3.7/site-packages/wandb/apis/normalize.py", line 26, in wrapper
    return func(*args, **kwargs)
  File "/home/dongheng/.conda/envs/LLMR/lib/python3.7/site-packages/wandb/sdk/internal/internal_api.py", line 1519, in upsert_run
    **kwargs,
  File "/home/dongheng/.conda/envs/LLMR/lib/python3.7/site-packages/wandb/sdk/lib/retry.py", line 129, in __call__
    retry_timedelta_triggered = check_retry_fn(e)
  File "/home/dongheng/.conda/envs/LLMR/lib/python3.7/site-packages/wandb/util.py", line 1049, in check_retry_fn
    return fallback_retry_fn(e)
  File "/home/dongheng/.conda/envs/LLMR/lib/python3.7/site-packages/wandb/util.py", line 996, in no_retry_auth
    raise CommError("Permission denied, ask the project owner to grant you access")
wandb.errors.CommError: Permission denied, ask the project owner to grant you access

During handling of the above exception, another exception occurred:

Traceback (most recent call last):
  File "/home/dongheng/.conda/envs/LLMR/lib/python3.7/site-packages/wandb/sdk/internal/internal_util.py", line 49, in run
    self._run()
  File "/home/dongheng/.conda/envs/LLMR/lib/python3.7/site-packages/wandb/sdk/internal/internal_util.py", line 100, in _run
    self._process(record)
  File "/home/dongheng/.conda/envs/LLMR/lib/python3.7/site-packages/wandb/sdk/internal/internal.py", line 309, in _process
    self._sm.send(record)
  File "/home/dongheng/.conda/envs/LLMR/lib/python3.7/site-packages/wandb/sdk/internal/sender.py", line 305, in send
    send_handler(record)
  File "/home/dongheng/.conda/envs/LLMR/lib/python3.7/site-packages/wandb/sdk/internal/sender.py", line 797, in send_run
    self._init_run(run, config_value_dict)
  File "/home/dongheng/.conda/envs/LLMR/lib/python3.7/site-packages/wandb/sdk/internal/sender.py", line 837, in _init_run
    commit=run.git.commit or None,
  File "/home/dongheng/.conda/envs/LLMR/lib/python3.7/site-packages/wandb/apis/normalize.py", line 62, in wrapper
    raise CommError(message, err).with_traceback(sys.exc_info()[2])
  File "/home/dongheng/.conda/envs/LLMR/lib/python3.7/site-packages/wandb/apis/normalize.py", line 26, in wrapper
    return func(*args, **kwargs)
  File "/home/dongheng/.conda/envs/LLMR/lib/python3.7/site-packages/wandb/sdk/internal/internal_api.py", line 1519, in upsert_run
    **kwargs,
  File "/home/dongheng/.conda/envs/LLMR/lib/python3.7/site-packages/wandb/sdk/lib/retry.py", line 129, in __call__
    retry_timedelta_triggered = check_retry_fn(e)
  File "/home/dongheng/.conda/envs/LLMR/lib/python3.7/site-packages/wandb/util.py", line 1049, in check_retry_fn
    return fallback_retry_fn(e)
  File "/home/dongheng/.conda/envs/LLMR/lib/python3.7/site-packages/wandb/util.py", line 996, in no_retry_auth
    raise CommError("Permission denied, ask the project owner to grant you access")
wandb.errors.CommError: Permission denied, ask the project owner to grant you access
